<?xml version="1.0" encoding="UTF-8"?>
<!-- Generated by org.testng.reporters.JUnitReportReporter -->
<testsuite skipped="2" hostname="SH852" name="com.xiaoyun.testcases.LoginTest1" tests="4" failures="1" timestamp="12 六月 2017 10:20:08 GMT" time="0.019" errors="0">
  <testcase name="f1" time="0.002" classname="com.xiaoyun.testcases.LoginTest1">
    <skipped/>
  </testcase> <!-- f1 -->
  <testcase name="f1" time="0.013" classname="com.xiaoyun.testcases.LoginTest1">
    <skipped/>
  </testcase> <!-- f1 -->
  <testcase name="f2" time="0.002" classname="com.xiaoyun.testcases.LoginTest1"/>
  <testcase name="f1" time="0.002" classname="com.xiaoyun.testcases.LoginTest1">
    <failure type="java.lang.AssertionError" message="断言失败">
      <![CDATA[java.lang.AssertionError: 断言失败
	at org.testng.Assert.fail(Assert.java:93)
	at com.xiaoyun.utils.AssertUtil.checkIntNum(AssertUtil.java:13)
	at com.xiaoyun.testcases.LoginTest1.f1(LoginTest1.java:22)
	at sun.reflect.NativeMethodAccessorImpl.invoke0(Native Method)
	at sun.reflect.NativeMethodAccessorImpl.invoke(Unknown Source)
	at sun.reflect.DelegatingMethodAccessorImpl.invoke(Unknown Source)
	at java.lang.reflect.Method.invoke(Unknown Source)
	at org.testng.internal.MethodInvocationHelper.invokeMethod(MethodInvocationHelper.java:108)
	at org.testng.internal.Invoker.invokeMethod(Invoker.java:661)
	at org.testng.internal.Invoker.retryFailed(Invoker.java:1014)
	at org.testng.internal.Invoker.invokeTestMethods(Invoker.java:1215)
	at org.testng.internal.TestMethodWorker.invokeTestMethods(TestMethodWorker.java:126)
	at org.testng.internal.TestMethodWorker.run(TestMethodWorker.java:109)
	at org.testng.TestRunner.privateRun(TestRunner.java:744)
	at org.testng.TestRunner.run(TestRunner.java:602)
	at org.testng.SuiteRunner.runTest(SuiteRunner.java:380)
	at org.testng.SuiteRunner.runSequentially(SuiteRunner.java:375)
	at org.testng.SuiteRunner.privateRun(SuiteRunner.java:340)
	at org.testng.SuiteRunner.run(SuiteRunner.java:289)
	at org.testng.SuiteRunnerWorker.runSuite(SuiteRunnerWorker.java:52)
	at org.testng.SuiteRunnerWorker.run(SuiteRunnerWorker.java:86)
	at org.testng.TestNG.runSuitesSequentially(TestNG.java:1301)
	at org.testng.TestNG.runSuitesLocally(TestNG.java:1226)
	at org.testng.TestNG.runSuites(TestNG.java:1144)
	at org.testng.TestNG.run(TestNG.java:1115)
	at org.testng.remote.AbstractRemoteTestNG.run(AbstractRemoteTestNG.java:132)
	at org.testng.remote.RemoteTestNG.initAndRun(RemoteTestNG.java:230)
	at org.testng.remote.RemoteTestNG.main(RemoteTestNG.java:76)
]]>
    </failure>
  </testcase> <!-- f1 -->
</testsuite> <!-- com.xiaoyun.testcases.LoginTest1 -->
